Workbook

Sheet sum pra sar
A2: Rekap pencairan subsidi
A3: Tahun | B3: Bulan | C3: Porsi Jakpro | E3: Porsi LRTJ | G3: Realisasi pencairan | J3: Keterangan
C4: Prasarana | D4: Sarana | E4: Prasarana | F4: Sarana | G4: Prasarana (a) | H4: Sarana (b) | I4: Total (a+b)
A5: 2019 | G5: ='[1]2019 - 2020'!$M$3 -> 17093417233 | H5: ='[1]2019 - 2020'!$N$3 -> 9661128221 | I5: ='[1]2019 - 2020'!$G$4 -> 26754545454
B6: Pengembalian lebih | G6: =-'[1]2019 - 2020'!$M$5 -> -1310129659 | H6: =-'[1]2019 - 2020'!$N$5 -> -4262215012 | I6: ='[1]2019 - 2020'!$G$5 -> -5572344673
B7: SubTotal | C7: 10790194404 | D7: 4328122969 | E7: 4993093169 | F7: 1070790240 | G7: =G5+G6 -> 15783287574 | H7: =H5+H6 -> 5398913209 | I7: =I5+I6 -> 21182200781
B8: Total | C8: =C7+D7 -> 15118317373 | E8: =E7+F7 -> 6063883409 | I8: =C8+E8-I7 -> 1
A10: 2020 | B10: UM | C10: 29863327091 | D10: 12151963218 | E10: 18491800335 | F10: 22679535213 | G10: ='[1]2019 - 2020'!$M$9 -> 48355127425 | H10: ='[1]2019 - 2020'!$N$9 -> 34831498431 | I10: ='[1]2019 - 2020'!$G$10 -> 83186625856
B11: Jan | C11: =53463699347+5933241767 -> 59396941114 | D11: =13543074359+1490958261 -> 15034032620 | E11: =8140009777+894981883 -> 9034991660 | F11: =25275803284+2782615432 -> 28058418716 | G11: ='[1]2019 - 2020'!$M$11 -> 68448565693 | H11: ='[1]2019 - 2020'!$N$11 -> 43075818417 | I11: ='[1]2019 - 2020'!$G$11+'[1]2019 - 2020'!$G$12 -> 111524384110
B12: Feb
B13: Mar
B14: Apr
B15: Mei
B16: Jun | C16: =10042162822+1115179643 -> 11157342465 | D16: =2681678559+295114729 -> 2976793288 | E16: =3285896843+360989202 -> 3646886045 | F16: =5004888693+550780542 -> 5555669235 | G16: ='[1]2019 - 2020'!$M$14+'[1]2019 - 2020'!$M$15 -> 14808955183 | H16: ='[1]2019 - 2020'!$N$14+'[1]2019 - 2020'!$N$15 -> 8527735850 | I16: ='[1]2019 - 2020'!$G$14+'[1]2019 - 2020'!$G$15 -> 23336691033
B17: Jul | C17: =8416921157+1100629677 -> 9517550834 | D17: =2163469683+304747967 -> 2468217650 | E17: =1787135055+297588895 -> 2084723950 | F17: =4037741556+568759313 -> 4606500869 | G17: ='[1]2019 - 2020'!$M$17+'[1]2019 - 2020'!$M$18 -> 1.160648e+10 | H17: ='[1]2019 - 2020'!$N$17+'[1]2019 - 2020'!$N$18 -> 7.0705135e+09 | I17: ='[1]2019 - 2020'!$G$17+'[1]2019 - 2020'!$G$18 -> 18676993304
B18: Aug | C18: =8229995313+1080151181 -> 9310146494 | D18: =2163469683+305066799 -> 2468536482 | E18: =854232348+195604565 -> 1049836913 | F18: =4037741556+569354357 -> 4607095913 | G18: ='[1]2019 - 2020'!$M$20+'[1]2019 - 2020'!$M$21 -> 1.0362226e+10 | H18: ='[1]2019 - 2020'!$N$20+'[1]2019 - 2020'!$N$21 -> 7.0733899e+09 | I18: ='[1]2019 - 2020'!$G$20+'[1]2019 - 2020'!$G$21 -> 17435615801
B19: Sep | C19: =3915628636+1098256948 -> 5013885584 | D19: =251285915+294935386 -> 546221301 | E19: =-1647910553+225172722 -> -1422737831 | F19: =468981650+550445830 -> 1019427480 | G19: ='[1]2019 - 2020'!$M$23+'[1]2019 - 2020'!$M$24 -> 3594245146 | H19: ='[1]2019 - 2020'!$N$23+'[1]2019 - 2020'!$N$24 -> 1.5625514e+09 | I19: ='[1]2019 - 2020'!$G$23+'[1]2019 - 2020'!$G$24 -> 5156796534
B20: Okt | C20: =3902547543+1096891358 -> 4999438901 | D20: =340675201+305365703 -> 646040904 | E20: =-1491061631+242856404 -> -1248205227 | F20: =635811274+569912210 -> 1205723484 | G20: ='[1]2019 - 2020'!$M$26+'[1]2019 - 2020'!$M$27 -> 3753987178 | H20: ='[1]2019 - 2020'!$N$26+'[1]2019 - 2020'!$N$27 -> 1.8490109e+09 | I20: ='[1]2019 - 2020'!$G$26+'[1]2019 - 2020'!$G$27 -> 5602998061
B21: Nov | C21: =12118463128+2175267757 -> 14293730885 | D21: =-356312246+296236617 -> -60075629 | E21: =-2520259202+232101788 -> -2288157414 | F21: =-664995110+552774349 -> -112220761 | G21: ='[1]2019 - 2020'!$M$29+'[1]2019 - 2020'!$M$30 -> 1.2007869e+10 | H21: ='[1]2019 - 2020'!$N$29+'[1]2019 - 2020'!$N$30 -> -1.7449193e+08 | I21: ='[1]2019 - 2020'!$G$29+'[1]2019 - 2020'!$G$30 -> 11833377083
B22: Dec | C22: =2492257349 -> 2492257349 | D22: =-266922960 -> -266922960 | E22: =10892728833 -> 10892728833 | F22: =-498165487 -> -498165487 | G22: ='[1]2019 - 2020'!$M$32 -> 1.3384986e+10 | H22: ='[1]2019 - 2020'!$N$32 -> -7.6508845e+08 | I22: ='[1]2019 - 2020'!$G$32 -> 12619897735
B23: Pengembalian lebih | C23: ='selish kurng 2020'!D25 -> 1.0169731e+09 | D23: ='selish kurng 2020'!D26 -> 3.0789643e+08 | E23: ='selish kurng 2020'!E25 -> -5.7430316e+09 | F23: ='selish kurng 2020'!E26 -> 5.6968331e+08 | G23: ='[1]2019 - 2020'!$M$34 -> -4.7191279e+09 | H23: ='[1]2019 - 2020'!$N$34 -> 8.7054917e+08 | I23: ='[1]2019 - 2020'!$G$34 -> -3848578768
B24: Subtotal | C24: =SUM(C10:C23) -> 1.4706159e+11 | D24: =SUM(D10:D23) -> 3.6272703e+10 | E24: =SUM(E10:E23) -> 3.4498836e+10 | F24: =SUM(F10:F23) -> 6.7691668e+10 | G24: =SUM(G10:G23) -> 1.8160331e+11 | H24: =SUM(H10:H23) -> 1.0392149e+11 | I24: =SUM(I10:I23) -> 285524800749
B25: Total | C25: =C24+D24 -> 1.833343e+11 | E25: =E24+F24 -> 102190503598 | I25: =C25+E25-I24 -> -0.099975586
A27: 2021 | B27: UM | C27: 11344848120 | D27: 15655151880 | E27: 11344848120 | F27: 15655151880 | G27: ='[1]2021'!$L$3 -> 22689696240 | H27: ='[1]2021'!$M$3 -> 31310303760 | I27: ='[1]2021'!$F$3 -> 54000000000
B28: Jan | C28: =7545424678+832915325 -> 8378340003 | D28: =15545040283+1727220698 -> 17272260981 | E28: =9918720418+1080201959 -> 10998922377 | F28: =27471474031+3032728577 -> 30504202608 | G28: ='[1]2021'!$L$5+'[1]2021'!$L$6 -> 19404605659 | H28: ='[1]2021'!$M$5+'[1]2021'!$M$6 -> 47749126306 | I28: ='[1]2021'!$G$5+'[1]2021'!$G$6 -> 67153731965
B29: Feb
B30: Mar
B31: Apr
B32: Mei
B33: Jun | C33: =1709256437+188717416 -> 1897973853 | D33: =3137986984+341986859 -> 3479973843 | E33: =2133644049+226969096 -> 2360613145 | F33: =6304928885+673597921 -> 6978526806 | G33: ='[1]2021'!$L$8+'[1]2021'!$L$9 -> 4269889429 | H33: ='[1]2021'!$M$8+'[1]2021'!$M$9 -> 10447198218 | I33: ='[1]2021'!$F$10 -> 14717087647
B34: Jul | C34: =533522821+184494548 -> 718017369 | D34: =1563858598+347462004 -> 1911320602 | E34: =1262564470+264338847 -> 1526903317 | F34: =-1611529667+(-5361089) -> -1616890756 | G34: ='[1]2021'!$L$11+'[1]2021'!$L$12 -> 2247760282 | H34: ='[1]2021'!$M$11+'[1]2021'!$M$12 -> 291590250 | I34: ='[1]2021'!$F$13 -> 2539350532
B35: Aug | C35: =494954414+180309777 -> 675264191 | D35: =1569384017+348028405 -> 1917412422 | E35: =1119154113+248683365 -> 1367837478 | F35: =63194845+180664579 -> 243859424 | G35: ='[1]2021'!$L$14+'[1]2021'!$L$15 -> 2045562655 | H35: ='[1]2021'!$M$14+'[1]2021'!$M$15 -> 2158811860 | I35: ='[1]2021'!$F$16 -> 4204373515
B36: Sep | C36: =-637465544+179598160 -> -457867384 | D36: =192712+347913677 -> 348106389 | E36: =906017496+347276243 -> 1253293739 | F36: =1522938677+517107672 -> 2040046349 | G36: ='[1]2021'!$L$17+'[1]2021'!$L$18 -> 802606530 | H36: ='[1]2021'!$M$17+'[1]2021'!$M$18 -> 2380972563 | I36: ='[1]2021'!$F$19 -> 3183579093
B37: Okt | C37: =-585354162+184842808 -> -400511354 | D37: =-4356685+347408188 -> 343051503 | E37: =-179286529+227636146 -> 48349617 | F37: =3418665174+727743950 -> 4146409124 | G37: ='[1]2021'!$L$20+'[1]2021'!$L$21 -> -345385296 | H37: ='[1]2021'!$M$20+'[1]2021'!$M$21 -> 4482684186 | I37: ='[1]2021'!$F$22 -> 4137298890
B38: Nov | C38: =8221642238+1163480575 -> 9385122813 | D38: =9831998+348984708 -> 358816706 | E38: =2624706486+533787245 -> 3158493731 | F38: =4382822203+834872509 -> 5217694712 | G38: ='[1]2021'!$L$23+'[1]2021'!$L$24 -> 12555714054 | H38: ='[1]2021'!$M$23+'[1]2021'!$M$24 -> 5564413908 | I38: ='[1]2021'!$F$25 -> 18120127962
B39: Dec | C39: =46908941363 -> 46908941363 | D39: =-8519318+6663543 -> -1855775 | E39: =17909820003 -> 17909820003 | F39: =6003946975+5844256-3240995296 -> 2768795935 | G39: ='[1]2021'!$L$26 -> 64818761366 | H39: ='[1]2021'!$M$26 -> 2766940160 | I39: ='[1]2021'!$F$28 -> 67585701525
B40: Selisih kurang/lebih | C40: =153130154401-SUM(C27:C39) -> 74680025427 | D40: =41721384244-SUM(D27:D39) -> 437145693 | E40: =61680270750-SUM(E27:E39) -> 11711189223 | F40: =65341845470-SUM(F27:F39) -> -595950612 | G40: ='[1]2021'!$L$30 -> 10012061342 | H40: ='[1]2021'!$M$30 -> 5722664668 | I40: ='[1]2021'!$G$30 -> 15734726010
B41: Kekurangan subsidi TA 2021 | G41: ='[1]2021'!$L$33 -> 70497677723 | I41: ='[1]2021'!$G$33 -> 70497677723
B42: Subtotal | C42: =SUM(C27:C41) -> 153130154401 | D42: =SUM(D27:D41) -> 41721384244 | E42: =SUM(E27:E41) -> 61680270750 | F42: =SUM(F27:F41) -> 65341845470 | G42: =SUM(G27:G41) -> 208998949984 | H42: =SUM(H27:H41) -> 112874705879 | I42: =SUM(I27:I41) -> 321873654862
B43: Total | C43: =C42+D42 -> 194851538645 | E43: =E42+F42 -> 127022116220 | I43: =C43+E43-I42 -> 3
...

Sheet kebut - real
B2: Periode Tahun | D2: Tanggal Perjanjian | E2: Nilai Kebutuhan | F2: Nilai Perjanjian / DPA | G2: Realisasi Pencairan | H2: Tgl Penagihan | I2: Tgl Pencairan | J2: selisih penciaran | K2: Keterangan
B3: 2019 | D3: 43809 | F3: 29727272727 | G3: 21182200781 | H3: 43812 | I3: 43819 | J3: =I3-H3 -> 7 | K3: biaya Prasarana tidak terverif 100%
B4: 2020 | D4: 43969 | E4: =241775637127+174157492155 -> 415933129282 | F4: 415933129282 | G4: 285524800749 | K4: Nilai Kebutuhan: BA Verif Pengusulan Subsidi 2020 - 3 Maret 2020 Nilai Perjanjian NO 2272/-1.811.3 tgl 18 Mei 2020 DPA 439.620.000.000
C5: Uang Muka | G5: ='[1]2019 - 2020'!$G$10 -> 83186625856 | H5: ='[1]2019 - 2020'!$D$9 -> 43980 | I5: ='[1]2019 - 2020'!$H$10 -> 44008 | J5: =I5-H5 -> 28
C6: Jan - Mei | G6: ='[1]2019 - 2020'!$G$11+'[1]2019 - 2020'!$G$12 -> 111524384110 | H6: ='[1]2019 - 2020'!$D$11 -> 44012 | I6: 44098 | J6: =I6-H6 -> 86
C7: Jun | G7: ='[1]2019 - 2020'!$G$14+'[1]2019 - 2020'!$G$15 -> 23336691033 | H7: ='[1]2019 - 2020'!$D$14 -> 44071 | I7: ='[1]2019 - 2020'!$H$14 -> 44194 | J7: =I7-H7 -> 123 | K7: pencairan dilakukan bersamaan periode Jun - Agust
C8: Jul | G8: ='[1]2019 - 2020'!$G$17+'[1]2019 - 2020'!$G$18 -> 18676993304 | H8: ='[1]2019 - 2020'!$D$17 -> 44102 | I8: ='[1]2019 - 2020'!$H$17 -> 44194 | J8: =I8-H8 -> 92
C9: Aug | G9: ='[1]2019 - 2020'!$G$20+'[1]2019 - 2020'!$G$21 -> 17435615801 | H9: ='[1]2019 - 2020'!$D$20 -> 44149 | I9: ='[1]2019 - 2020'!$H$20 -> 44194 | J9: =I9-H9 -> 45
C10: Sep | G10: ='[1]2019 - 2020'!$G$23+'[1]2019 - 2020'!$G$24 -> 5156796534 | H10: ='[1]2019 - 2020'!$D$23 -> 44173 | I10: ='[1]2019 - 2020'!$H$23 -> 44195 | J10: =I10-H10 -> 22
C11: Okt | G11: ='[1]2019 - 2020'!$G$26+'[1]2019 - 2020'!$G$27 -> 5602998061 | H11: ='[1]2019 - 2020'!$D$26 -> 44175 | I11: ='[1]2019 - 2020'!$H$26 -> 44195 | J11: =I11-H11 -> 20
C12: Nov | G12: ='[1]2019 - 2020'!$G$29+'[1]2019 - 2020'!$G$30 -> 11833377083 | H12: ='[1]2019 - 2020'!$D$29 -> 44182 | I12: ='[1]2019 - 2020'!$H$29 -> 44195 | J12: =I12-H12 -> 13
C13: Dec | G13: ='[1]2019 - 2020'!$G$32 -> 12619897735 | H13: ='[1]2019 - 2020'!$D$32 -> 44182 | I13: ='[1]2019 - 2020'!$H$32 -> 44195 | J13: =I13-H13 -> 13
C14: Selisih Lebih | G14: ='[1]2019 - 2020'!$E$34 -> -3848578768 | K14: pengembalian kelebihan subsidi
B15: 2021 | D15: 44368 | E15: =112487557423+228812523458 -> 341300080881 | F15: =270000000000+70497677723 -> 340497677723 | G15: ='[1]2021'!$G$36 -> 321873654862 | K15: - Kebutuhan; BA Addendum 10 Des 2021 '-Perjanjian ; 52/-1.811.3 tgl 21 Juni 2021 & DPA, addendum merubah porsi prasarana - sarana, Utang subsidi 70.497.677.723 (Addendum th 2022 -31 Des 2022)
C16: Uang Muka | G16: ='[1]2021'!$G$3 -> 54000000000 | H16: ='[1]2021'!$D$3 -> 44368 | I16: ='[1]2021'!$H$3 -> 44384 | J16: =I16-H16 -> 16
C17: Jan - Mei | G17: ='[1]2021'!$G$5+'[1]2021'!$G$6 -> 67153731965 | H17: ='[1]2021'!$D$5 -> 44439 | I17: ='[1]2021'!$H$5 -> 44455 | J17: =I17-H17 -> 16
C18: Jun | G18: ='[1]2021'!$E$8+'[1]2021'!$E$9 -> 14717087647 | H18: ='[1]2021'!$D$8 -> 44462 | I18: 44537 | J18: =I18-H18 -> 75
C19: Jul | G19: ='[1]2021'!$E$11+'[1]2021'!$E$12 -> 2539350532 | H19: ='[1]2021'!$D$11 -> 44462 | I19: 44537 | J19: =I19-H19 -> 75
C20: Aug | G20: ='[1]2021'!$E$14+'[1]2021'!$E$15 -> 4204373515 | H20: ='[1]2021'!$D$14 -> 44487 | I20: 44537 | J20: =I20-H20 -> 50
C21: Sep | G21: ='[1]2021'!$E$17+'[1]2021'!$E$18 -> 3183579093 | H21: ='[1]2021'!$D$17 -> 44519 | I21: 44558 | J21: =I21-H21 -> 39
C22: Okt | G22: ='[1]2021'!$E$20+'[1]2021'!$E$21 -> 4137298890 | H22: ='[1]2021'!$D$20 -> 44544 | I22: 44558 | J22: =I22-H22 -> 14
C23: Nov | G23: ='[1]2021'!$E$23+'[1]2021'!$E$24 -> 18120127962 | H23: ='[1]2021'!$D$23 -> 44547 | I23: 44558 | J23: =I23-H23 -> 11
C24: Dec | G24: ='[1]2021'!$E$26 -> 67585701525 | H24: ='[1]2021'!$D$26 -> 44547 | I24: 44558 | J24: =I24-H24 -> 11
C25: Selisih Kurang | G25: ='[1]2021'!$F$30+'[1]2021'!$F$33 -> 86232403733 | H25: ='[1]2021'!$D$30 -> 44895 | I25: ='[1]2021'!$H$30 -> 44910 | J25: =I25-H25 -> 15 | K25: penyesuaian subsidi Jan - Nov
B26: 2022 | D26: 44673 | E26: =180919133395+278202865470 -> 459121998865 | F26: =362172050000+46441290106 -> 408613340106 | G26: 400261726561 | K26: - Kebutuhan ; BA Proposal 30 maret 2022 '- Perjanjian; Perjanjian 22 Apr 2022 & DPA-P utang 2022 = 46.441.290.106
C27: Uang Muka | G27: ='[1]2022'!$L$3 -> 72434410000 | H27: ='[1]2022'!$E$3 -> 44673 | I27: ='[1]2022'!$M$3 -> 44679 | J27: =I27-H27 -> 6
C28: Jan - Apr | G28: ='[1]2022'!$K$5+'[1]2022'!$K$6 -> 93173556982 | H28: ='[1]2022'!$E$5 -> 44721 | I28: 44739 | J28: =I28-H28 -> 18
C29: Mei | G29: ='[1]2022'!$L$8 -> 23329524874 | H29: ='[1]2022'!$E$8 -> 44747 | I29: ='[1]2022'!$M$8 -> 44770 | J29: =I29-H29 -> 23
C30: Jun | G30: ='[1]2022'!$L$11 -> 22909938731 | H30: ='[1]2022'!$E$11 -> 44789 | I30: ='[1]2022'!$M$11 -> 44805 | J30: =I30-H30 -> 16
C31: Jul | G31: ='[1]2022'!$L$14 -> 12459447111 | H31: ='[1]2022'!$E$14 -> 44833 | I31: ='[1]2022'!$M$14 -> 44846 | J31: =I31-H31 -> 13
C32: Aug | G32: ='[1]2022'!$L$17 -> 21973072946 | H32: ='[1]2022'!$E$17 -> 44834 | I32: ='[1]2022'!$M$17 -> 44845 | J32: =I32-H32 -> 11
C33: Sep | G33: ='[1]2022'!$L$20 -> 9.3639775e+09 | H33: ='[1]2022'!$E$20 -> 44869 | I33: ='[1]2022'!$M$20 -> 44887 | J33: =I33-H33 -> 18
C34: Okt | G34: ='[1]2022'!$L$23 -> 1.3295133e+10 | H34: ='[1]2022'!$E$23 -> 44897 | I34: ='[1]2022'!$M$23 -> 44909 | J34: =I34-H34 -> 12
C35: Nov | G35: ='[1]2022'!$L$26 -> 5.3675678e+10 | H35: ='[1]2022'!$E$26 -> 44911 | I35: ='[1]2022'!$M$26 -> 44923 | J35: =I35-H35 -> 12
C36: Dec | G36: ='[1]2022'!$L$29 -> 29431960165 | H36: ='[1]2022'!$E$29 -> 44911 | I36: ='[1]2022'!$M$29 -> 44923 | J36: =I36-H36 -> 12
C37: Selisih Kurang | G37: ='[1]2022'!$L$32 -> 46441290106 | H37: ='[1]2022'!$E$32 -> 45266 | I37: ='[1]2022'!$M$32 -> 45278 | J37: =I37-H37 -> 12
C38: Selisih lebih PTLRTJ | G38: ='[1]2022'!$L$33 -> 1773736876 | H38: ='[1]2022'!$E$33 -> 45484 | I38: ='[1]2022'!$M$33 -> 45497 | J38: =I38-H38 -> 13
B39: 2023 | D39: 45030 | E39: 506990038251 | F39: =350000000000+105884366450 -> 455884366450 | G39: ='[2]2023'!$S$48 -> 4.5191735e+11 | K39: - kebutuhan; perjanjian 14 Apr 2023 - perjanjian; addendum 6 des 2023 + DPA-P utang 2023 = 105.884.366.450
C40: Uang Muka | G40: ='[2]2023'!$R$3 -> 70000000000 | H40: ='[2]2023'!$K$3 -> 45033 | I40: ='[2]2023'!$T$3 -> 45071 | J40: =I40-H40 -> 38
C41: Jan | G41: ='[2]2023'!$Q$5 -> 27165209395 | H41: 45096 | I41: 45111 | J41: =I41-H41 -> 15
...

Sheet selish kurng 2020
A1: Selish Kurang 2020
C2: total | D2: Jakpro | E2: LRT
A3: terverif | B3: Prasarana | C3: =D3+E3 -> 20754740097 | D3: 10975062255 | E3: =9779677842 -> 9779677842
B4: Sarana | C4: =D4+E4 -> 8825317956 | D4: 3078964271 | E4: 5746353685
C6: =D6+E6 -> 83186625856 | D6: ='[1]2019 - 2020'!$J$9 -> 42015270308 | E6: ='[1]2019 - 2020'!$I$9 -> 41171355548
A7: UM | B7: Prasarana | C7: =D7+E7 -> 4.8355127e+10 | D7: =149316635453*20% -> 2.9863327e+10 | E7: 18491800335
B8: Sarana | C8: =D8+E8 -> 3.4831498e+10 | D8: =60759816089*20% -> 1.2151963e+10 | E8: 22679535213
A10: 25% UM | B10: Prasarana | C10: =D10+E10 -> 1.2088782e+10 | D10: =D7*25% -> 7.4658318e+09 | E10: =E7*25% -> 4.6229501e+09
B11: Sarana | C11: =D11+E11 -> 8.7078746e+09 | D11: =D8*25% -> 3.0379908e+09 | E11: =E8*25% -> 5.6698838e+09
A13: sanksi | B13: Prasarana | C13: 7030562 | E13: =C13 -> 7030562
B14: Sarana | C14: 4952060 | E14: =C14 -> 4952060
A17: total nilai verif | B17: Prasarana | C17: =C3-C10-C13 -> 8.6589277e+09 | D17: =D3-D10-D13 -> 3.5092305e+09 | E17: =E3-E10-E13 -> 5.1496972e+09
B18: Sarana | C18: =C4-C11-C14 -> 1.1249129e+08 | D18: =D4-D11-D14 -> 40973467 | E18: =E4-E11-E14 -> 71517822
B19: Total | C19: =C17+C18 -> 8.771419e+09 | D19: =D17+D18 -> 3.5502039e+09 | E19: =E17+E18 -> 5221215018
A21: pencairan 90% des | B21: Prasarana | C21: =D21+E21 -> 13384986182 | D21: ='sum pra sar'!C22 -> 2492257349 | E21: ='sum pra sar'!E22 -> 10892728833
B22: Sarana | C22: =D22+E22 -> -765088447 | D22: ='sum pra sar'!D22 -> -266922960 | E22: ='sum pra sar'!F22 -> -498165487
B23: Total | C23: =D23+E23 -> 12619897735 | D23: =D21+D22 -> 2225334389 | E23: =E21+E22 -> 10394563346
A25: selisih kurang lebih | B25: Prasarana | C25: =D25+E25 -> -4.7260585e+09 | D25: =D17-D21 -> 1.0169731e+09 | E25: =E17-E21 -> -5.7430316e+09
B26: Sarana | C26: =D26+E26 -> 8.7757974e+08 | D26: =D18-D22 -> 3.0789643e+08 | E26: =E18-E22 -> 5.6968331e+08
B27: Total | C27: =D27+E27 -> -3.8484788e+09 | D27: =D25+D26 -> 1.3248696e+09 | E27: =E25+E26 -> -5173348328

Sheet selish kurng 2021
A1: Selish Kurang 2020
C2: total | D2: Jakpro | E2: LRT
A3: terverif | B3: Prasarana | C3: =D3+E3 -> 0
B4: Sarana | C4: =D4+E4 -> 0
C6: =D6+E6 -> 83186625856 | D6: ='[1]2019 - 2020'!$J$9 -> 42015270308 | E6: ='[1]2019 - 2020'!$I$9 -> 41171355548
A7: UM | B7: Prasarana | C7: =D7+E7 -> 0
B8: Sarana | C8: =D8+E8 -> 0
A10: 25% UM | B10: Prasarana | C10: =D10+E10 -> 0 | D10: =D7*25% -> 0 | E10: =E7*25% -> 0
B11: Sarana | C11: =D11+E11 -> 0 | D11: =D8*25% -> 0 | E11: =E8*25% -> 0
A13: sanksi | B13: Prasarana | C13: 7030562
B14: Sarana | C14: 4952060
A17: total nilai verif | B17: Prasarana | C17: =C3-C10-C13 -> -7030562 | D17: =D3-D10-D13 -> 0 | E17: =E3-E10-E13 -> 0
B18: Sarana | C18: =C4-C11-C14 -> -4952060 | D18: =D4-D11-D14 -> 0 | E18: =E4-E11-E14 -> 0
B19: Total | C19: =C17+C18 -> -11982622 | D19: =D17+D18 -> 0 | E19: =E17+E18 -> 0
A21: pencairan 90% des | B21: Prasarana | C21: =D21+E21 -> 0
B22: Sarana | C22: =D22+E22 -> 0
B23: Total | C23: =D23+E23 -> 0 | D23: =D21+D22 -> 0 | E23: =E21+E22 -> 0
A25: selisih kurang lebih | B25: Prasarana | C25: =D25+E25 -> 0 | D25: =D17-D21 -> 0 | E25: =E17-E21 -> 0
B26: Sarana | C26: =D26+E26 -> 0 | D26: =D18-D22 -> 0 | E26: =E18-E22 -> 0
B27: Total | C27: =D27+E27 -> 0 | D27: =D25+D26 -> 0 | E27: =E25+E26 -> 0
